<?xml version="1.0"?>
<robot xmlns:xacro="http://ros.org/wiki/xacro" name="prius">

  <!-- Arguments -->
  <xacro:arg name="namespace" default=""/>

  <!--- Surface properties must come first? -->
  <gazebo reference="front_left_wheel">
    <mu1>0.9</mu1>
    <mu2>0.9</mu2>
    <minDepth>0.005</minDepth>
    <kp>1e8</kp>
  </gazebo>
  <gazebo reference="front_right_wheel">
    <mu1>0.9</mu1>
    <mu2>0.9</mu2>
    <minDepth>0.005</minDepth>
    <kp>1e8</kp>
  </gazebo>
  <gazebo reference="rear_left_wheel">
    <mu1>0.9</mu1>
    <mu2>0.9</mu2>
    <minDepth>0.005</minDepth>
    <kp>1e8</kp>
  </gazebo>
  <gazebo reference="rear_right_wheel">
    <mu1>0.9</mu1>
    <mu2>0.9</mu2>
    <minDepth>0.005</minDepth>
    <kp>1e8</kp>
  </gazebo>

   <!--       
  <link name="dummy"/>
  <joint name="dummy_joint" type="fixed">
    <parent link="dummy"/>
    <child link="base_link"/>
  </joint>-->
  
  <link name="$(arg namespace)base_link">
    <inertial>
      <mass value="1" />
      <inertia ixx="50.00" ixy="0.0" ixz="0.0" iyy="50.00" iyz="0.0" izz="50.00" />
    </inertial>
  </link>
  <joint name="base_link_connection" type="fixed">
    <parent link="$(arg namespace)base_link" />
    <child link="$(arg namespace)chassis" />
    <origin xyz="1.45 0 0" rpy="0 0 1.57" />
    <axis xyz="1 0 0" />
  </joint>

  <link name="$(arg namespace)chassis">
    <visual>
      <origin xyz="0 0 0" rpy="0 0 0" />
      <geometry>
        <mesh filename="package://prius_description/meshes/hybrid_body.obj" scale="0.01 0.01 0.01" />
      </geometry>
    </visual>

    <collision name="chassis">
      <origin xyz="0.0 0.05 0.625" rpy="0 0 0" />
      <geometry>
        <box size="1.7526 2.1 0.95" />
      </geometry>
    </collision>

    <collision name="front_bumper">
      <origin xyz="0.0 -2.0 0.458488" rpy="0.0 0 0" />
      <geometry>
        <box size="1.337282 0.48 0.566691" />
      </geometry>
    </collision>

    <collision name="hood">
      <origin xyz="0.0 -1.900842 0.676305" rpy="0.341247 0 0" />
      <geometry>
        <box size="1.597968 0.493107 0.265468" />
      </geometry>
    </collision>

    <collision name="windshield">
      <origin xyz="0.0 -0.875105 1.032268" rpy="0.335476 0 0" />
      <geometry>
        <box size="1.168381 1.654253 0.272347" />
      </geometry>
    </collision>

    <collision name="top_front">
      <origin xyz="0.0 0.161236 1.386042" rpy="0.135030 0 0" />
      <geometry>
        <box size="1.279154 0.625988 0.171868" />
      </geometry>
    </collision>

    <collision name="top_rear">
      <origin xyz="0.0 0.817696 1.360069" rpy="-0.068997 0 0" />
      <geometry>
        <box size="1.285130 0.771189 0.226557" />
      </geometry>
    </collision>

    <collision name="rear_window">
      <origin xyz="0.0 1.640531 1.175126" rpy="-0.262017 0 0" />
      <geometry>
        <box size="1.267845 1.116344 0.244286" />
      </geometry>
    </collision>

    <collision name="trunk">
      <origin xyz="0.0 1.637059 0.888180" rpy="0.0 0 0" />
      <geometry>
        <box size="1.788064 1.138988 0.482746" />
      </geometry>
    </collision>

    <collision name="back_bumper">
      <origin xyz="0.0 2.054454 0.577870" rpy="0.0 0 0" />
      <geometry>
        <box size="1.781650 0.512093 0.581427" />
      </geometry>
    </collision>

    <inertial>
      <mass value="1356.0" />
      <origin xyz="0 0 0.48" rpy="0 0 1.5708" />
      <inertia ixx="2681.95008628" ixy="0.0" ixz="0.0" iyy="2681.95008628" iyz="0.0" izz="2681.95008628" />
    </inertial>
  </link>
  <link name="$(arg namespace)fl_axle">
    <inertial>
      <mass value="1" />
      <origin xyz="0 0 0" />
      <inertia ixx="50.0" ixy="0.0" ixz="0.0" iyy="50.0" iyz="0.0" izz="50.0" />
    </inertial>
  </link>
  <link name="$(arg namespace)fr_axle">
    <inertial>
      <mass value="1" />
      <origin xyz="0 0 0" />
      <inertia ixx="50.0" ixy="0.0" ixz="0.0" iyy="50.0" iyz="0.0" izz="50.0" />
    </inertial>
  </link>
  <link name="$(arg namespace)front_left_wheel">
    <inertial>
      <mass value="11" />
      <origin xyz="0 0 0" />
      <inertia ixx="50.0" ixy="0.0" ixz="0.0" iyy="50.0" iyz="0.0" izz="50.0" />
    </inertial>
    <collision name="front_left_wheel_collision">
      <geometry>
        <sphere radius="0.31265" />
      </geometry>
    </collision>
    <visual>
      <origin xyz="0 0 0" rpy="0 0 0" />
      <geometry>
        <mesh filename="package://prius_description/meshes/wheel.obj" scale="0.01 0.01 0.01" />
      </geometry>
    </visual>
  </link>
  <link name="$(arg namespace)front_right_wheel">
    <inertial>
      <mass value="11" />
      <origin xyz="0 0 0" />
      <inertia ixx="50.0" ixy="0.0" ixz="0.0" iyy="50.0" iyz="0.0" izz="50.0" />
    </inertial>
    <collision name="front_right_wheel_collision">
      <geometry>
        <sphere radius="0.31265" />
      </geometry>
    </collision>
    <visual>
      <origin xyz="0 0 0" rpy="0 0 0" />
      <geometry>
        <mesh filename="package://prius_description/meshes/wheel.obj" scale="0.01 0.01 0.01" />
      </geometry>
    </visual>
  </link>
  <link name="$(arg namespace)rear_left_wheel">
    <inertial>
      <mass value="11" />
      <origin xyz="0 0 0" />
      <inertia ixx="50.0" ixy="0.0" ixz="0.0" iyy="50.0" iyz="0.0" izz="50.0" />
    </inertial>
    <collision name="rear_left_wheel_collision">
      <geometry>
        <sphere radius="0.31265" />
      </geometry>
    </collision>
    <visual>
      <origin xyz="0 0 0" rpy="0 0 0" />
      <geometry>
        <mesh filename="package://prius_description/meshes/wheel.obj" scale="0.01 0.01 0.01" />
      </geometry>
    </visual>
  </link>
  <link name="$(arg namespace)rear_right_wheel">
    <inertial>
      <mass value="11" />
      <origin xyz="0 0 0" />
      <inertia ixx="50.0" ixy="0.0" ixz="0.0" iyy="50.0" iyz="0.0" izz="50.0" />
    </inertial>
    <collision name="rear_right_wheel_collision">
      <geometry>
        <sphere radius="0.31265" />
      </geometry>
    </collision>
    <visual>
      <origin xyz="0 0 0" rpy="0 0 0" />
      <geometry>
        <mesh filename="package://prius_description/meshes/wheel.obj" scale="0.01 0.01 0.01" />
      </geometry>
    </visual>
  </link>
  


  <joint name="front_left_steer_joint" type="continuous">
    <parent link="$(arg namespace)chassis" />
    <child link="$(arg namespace)fl_axle" />
    <origin xyz="0.767 -1.41 0.3" rpy="0 0 0" />
    <axis xyz="0 0 1" />
    <limit lower="-0.8727" upper="0.8727" effort="10000000" velocity="1000000" />
  </joint>
  <joint name="front_right_steer_joint" type="continuous">
    <parent link="$(arg namespace)chassis" />
    <child link="$(arg namespace)fr_axle" />
    <origin xyz="-0.767 -1.41 0.3" rpy="0 0 0" />
    <axis xyz="0 0 1" />
    <limit lower="-0.8727" upper="0.8727" effort="10000000" velocity="1000000" />
  </joint>
  <joint name="front_left_wheel_joint" type="continuous">
    <parent link="$(arg namespace)fl_axle" />
    <child link="$(arg namespace)front_left_wheel" />
    <origin xyz="0 0 0" rpy="0 0 0" />
    <axis xyz="1 0 0" />
  </joint>
  <joint name="front_right_wheel_joint" type="continuous">
    <parent link="$(arg namespace)fr_axle" />
    <child link="$(arg namespace)front_right_wheel" />
    <origin xyz="0 0 0" rpy="0 0 0" />
    <axis xyz="1 0 0" />
  </joint>
  <joint name="rear_left_wheel_joint" type="continuous">
    <parent link="$(arg namespace)chassis" />
    <child link="$(arg namespace)rear_left_wheel" />
    <origin xyz="0.793 1.45 0.3" rpy="0 0 0" />
    <axis xyz="1 0 0" />
  </joint>
  <joint name="rear_right_wheel_joint" type="continuous">
    <parent link="$(arg namespace)chassis" />
    <child link="$(arg namespace)rear_right_wheel" />
    <origin xyz="-0.793 1.45 0.3" rpy="0 0 0" />
    <axis xyz="1 0 0" />
  </joint>

  <gazebo reference="base_link_connection">
    <disableFixedJointLumping>true</disableFixedJointLumping>
  </gazebo>

  <gazebo>
    <plugin name="object_controller" filename="libgazebo_ros_planar_move.so">
      <commandTopic>cmd_vel</commandTopic>
      <odometryTopic>odom</odometryTopic>
      <odometryFrame>odom</odometryFrame>
      <odometryRate>20.0</odometryRate>
      <robotBaseFrame>base_footprint</robotBaseFrame>
    </plugin>
  </gazebo>
</robot>